<?xml version="1.0" ?>
<robot xmlns:xacro="http://ros.org/wiki/xacro">
	<xacro:macro name="motoman_mh5l" params="prefix">
		<!-- link list -->
		<link name="${prefix}base_link">
			<visual>
				<origin xyz="0 0 0" rpy="0 0 0"/>
				<geometry>
					<mesh filename="package://motoman_mh5_support/meshes/mh5l/visual/base_link.dae" />
				</geometry>
				<material name="blue">
					<color rgba="0 0 1 1"/>
				</material>
			</visual>
			<collision>
				<origin xyz="0 0 0" rpy="0 0 0"/>
				<geometry>
					<mesh filename="package://motoman_mh5_support/meshes/mh5l/collision/base_link.stl" />
				</geometry>
				<material name="yellow">
					<color rgba="0 1 1 1"/>
				</material>
			</collision>
		</link>
		<link name="${prefix}link_s">
			<visual>
				<origin xyz="0 0 0" rpy="0 0 0"/>
				<geometry>
					<mesh filename="package://motoman_mh5_support/meshes/mh5l/visual/link_1.dae"/>
				</geometry>
				<material name="silver">
					<color rgba="0.8 0.8 0.8 1"/>
				</material>
			</visual>
			<collision>
				<origin xyz="0 0 0" rpy="0 0 0"/>
				<geometry>
					<mesh filename="package://motoman_mh5_support/meshes/mh5l/collision/link_1.stl" />
				</geometry>
				<material name="yellow"/>
			</collision>
		</link>
		<link name="${prefix}link_l">
			<visual>
				<geometry>
					<mesh filename="package://motoman_mh5_support/meshes/mh5l/visual/link_2.dae"/>
				</geometry>
				<material name="blue"/>
			</visual>
			<collision>
				<geometry>
					<mesh filename="package://motoman_mh5_support/meshes/mh5l/collision/link_2.stl" />
				</geometry>
				<material name="yellow"/>
			</collision>
		</link>
		<link name="${prefix}link_u">
			<visual>
				<geometry>
					<mesh filename="package://motoman_mh5_support/meshes/mh5l/visual/link_3.dae"/>
				</geometry>
				<material name="blue"/>
			</visual>
			<collision>
				<geometry>
					<mesh filename="package://motoman_mh5_support/meshes/mh5l/collision/link_3.stl" />
				</geometry>
				<material name="yellow"/>
			</collision>
		</link>
		<link name="${prefix}link_r">
			<visual>
				<geometry>
					<mesh filename="package://motoman_mh5_support/meshes/mh5l/visual/link_4.dae"/>
				</geometry>
				<material name="silver"/>
			</visual>
			<collision>
				<geometry>
					<mesh filename="package://motoman_mh5_support/meshes/mh5l/collision/link_4.stl" />
				</geometry>
				<material name="yellow"/>
			</collision>
		</link>
		<link name="${prefix}link_b">
			<visual>
				<geometry>
					<mesh filename="package://motoman_mh5_support/meshes/mh5l/visual/link_5.dae"/>
				</geometry>
				<material name="blue"/>
			</visual>
			<collision>
				<geometry>
					<mesh filename="package://motoman_mh5_support/meshes/mh5l/collision/link_5.stl" />
				</geometry>
				<material name="yellow"/>
			</collision>
		</link>
		<link name="${prefix}link_t">
			<visual>
				<origin xyz="0 0 0" rpy="0 0 0"/>
				<geometry>
					<mesh filename="package://motoman_mh5_support/meshes/mh5l/visual/link_6.dae" />
				</geometry>
				<material name="silver"/>
			</visual>
			<collision>
				<origin xyz="0 0 0" rpy="0 0 0"/>
				<geometry>
					<mesh filename="package://motoman_mh5_support/meshes/mh5l/collision/link_6.stl" />
				</geometry>
				<material name="yellow"/>
			</collision>
		</link>
		<!-- end of link list -->
		<!-- joint list -->
		<joint name="${prefix}joint_s" type="revolute">
			<parent link="${prefix}base_link"/>
			<child link="${prefix}link_s"/>
			<origin xyz="0 0 0.330" rpy="0 0 0"/>
			<axis xyz="0 0 1" />
			<limit lower="-2.9671" upper="2.9671" effort="0" velocity="4.7124" />
		</joint>
		<joint name="${prefix}joint_l" type="revolute">
			<parent link="${prefix}link_s"/>
			<child link="${prefix}link_l"/>
			<origin xyz="0.088 0 0" rpy="0 0 0"/>
			<axis xyz="0 1 0" />
			<limit lower="-1.1345" upper="2.6179" effort="0" velocity="4.8869" />
		</joint>
		<joint name="${prefix}joint_u" type="revolute">
			<parent link="${prefix}link_l"/>
			<child link="${prefix}link_u"/>
			<origin xyz="0 0 0.400" rpy="0 0 0"/>
			<axis xyz="0 -1 0" />
      <!-- Old limits: lower="-2.3736" upper="4.4506" The new limits
           below were measured from an MH5F.  They ensure that link_r
           won't hit link_l even when joint_r is at 45 degrees.  The
           old limits were converted directly from the MH5 data sheet,
           which was clearly way off. -->
			<limit lower="-1.0122" upper="3.2218" effort="0" velocity="5.2359" />
		</joint>
		<joint name="${prefix}joint_r" type="revolute">
			<parent link="${prefix}link_u"/>
			<child link="${prefix}link_r"/>
			<origin xyz="0 0 0.040" rpy="0 0 0"/>
			<axis xyz="-1 0 0" />
			<limit lower="-3.3161" upper="3.3161" effort="0" velocity="7.8539" />
		</joint>
		<joint name="${prefix}joint_b" type="revolute">
			<parent link="${prefix}link_r"/>
			<child link="${prefix}link_b"/>
			<origin xyz="0.405 0 0" rpy="0 0 0"/>
			<axis xyz="0 -1 0" />
			<limit lower="-2.1817" upper="2.1817" effort="0" velocity="7.8539" />
		</joint>
		<joint name="${prefix}joint_t" type="revolute">
			<parent link="${prefix}link_b"/>
			<child link="${prefix}link_t"/>
			<origin xyz="0.0865 0 0" rpy="0 0 0"/>
			<axis xyz="-1 0 0" />
			<limit lower="-6.2831" upper="6.2831" effort="0" velocity="12.566" />
		</joint>
		<!-- end of joint list -->
	</xacro:macro>
</robot>
